Workbook

Sheet Maths
X1: Avg Power [MW] | Y1: =J37 -> 0.0016 | Z1: =J36 -> 0.01 | AA1: =J38 -> 1
X2: DC:AC | Y2: 1.1 | Z2: 1.2 | AA2: 1.3
A3: year | B3: Ga in Chip | C3: unit | D3: Source1 | E3: Notes1 | G3: Chips per inverter [#/inverter type] | H3: # of Phases | I3: Voltages [V] | J3: Power Rating [MW] | K3: Inverter Description | L3: SELECTED AS REPRESENTATIVE DESIGN | M3: Source2 | N3: Notes2 | P3: GaN market share | Q3: unit | R3: Source | S3: Notes (vs Si or SiC) | U3: Micro [g/inverter] | V3: String [g/inverter] | W3: Utility [g/inverter] | Y3: Micro [kg/MWac] | Z3: String [kg/MWac] | AA3: Utility [kg/MWac] | AC3: Microinverter Market Share (% by units) | AD3: String Inverter Market Share (% by units) | AE3: Central Inverter Market Share (% by units) | AG3: Marketshare Avg Ga for inverters [kg/MWac]
A4: 1990
A5: 1991
A6: 1992
A7: 1993
A8: 1994
A9: 1995 | AC9: 0.74244431 | AD9: 0.25270532 | AE9: 0.0048503749
A10: 1996 | AC10: 0.74244431 | AD10: 0.25270532 | AE10: 0.0048503749
A11: 1997 | AC11: 0.74244431 | AD11: 0.25270532 | AE11: 0.0048503749
A12: 1998 | AC12: 0.74244431 | AD12: 0.25270532 | AE12: 0.0048503749
A13: 1999 | AC13: 0.74244431 | AD13: 0.25270532 | AE13: 0.0048503749
A14: 2000 | AC14: 0.74244431 | AD14: 0.25270532 | AE14: 0.0048503749
A15: 2001 | AC15: 0.74244431 | AD15: 0.25270532 | AE15: 0.0048503749
A16: 2002 | AC16: 0.74244431 | AD16: 0.25270532 | AE16: 0.0048503749
A17: 2003 | AC17: 0.74244431 | AD17: 0.25270532 | AE17: 0.0048503749
A18: 2004 | AC18: 0.74244431 | AD18: 0.25270532 | AE18: 0.0048503749
A19: 2005 | AC19: 0.74244431 | AD19: 0.25270532 | AE19: 0.0048503749
A20: 2006 | AC20: 0.74244431 | AD20: 0.25270532 | AE20: 0.0048503749
... A27: 2013 | AC27: 0.74244431 | AD27: 0.25270532 | AE27: 0.0048503749
A28: 2014 | G28: *Heather will go back and inventory all the GaN TI ref designs adding # of phases and Voltage | AC28: 0.74244431 | AD28: 0.25270532 | AE28: 0.0048503749
A29: 2015 | B29: 5.12 | C29: g/cm^3 | D29: Han, Zhongkui, Qiance Liu, Xin Ouyang, Huiling Song, Tianming Gao, Yanfei Liu, Bojie Wen, and Tao Dai. 2024. “Tracking Two Decades of Global Gallium Stocks and Flows: A Dynamic Material Flow Analysis.” Resources, Conservation and Recycling 202 (March):107391. https://doi.org/10.1016/j.resconrec.2023.107391. | E29: Table S3, from Lovik 2016 * thickness of chip | AC29: =WoodMacInverterCompany!T4 -> 0.74244431 | AD29: =WoodMacInverterCompany!U4 -> 0.25270532 | AE29: =WoodMacInverterCompany!V4 -> 0.0048503749
A30: 2016 | B30: =1*10^-4 -> 0.0001 | C30: m thickness of chip | D30: Han, Zhongkui, Qiance Liu, Xin Ouyang, Huiling Song, Tianming Gao, Yanfei Liu, Bojie Wen, and Tao Dai. 2024. “Tracking Two Decades of Global Gallium Stocks and Flows: A Dynamic Material Flow Analysis.” Resources, Conservation and Recycling 202 (March):107391. https://doi.org/10.1016/j.resconrec.2023.107391. | E30: Table S3, from Lovik 2016 * thickness of chip * lots of losses | AC30: =WoodMacInverterCompany!T5 -> 0.75283328 | AD30: =WoodMacInverterCompany!U5 -> 0.24140776 | AE30: =WoodMacInverterCompany!V5 -> 0.0057589593
A31: 2017 | P31: % GaN HEMT in PV application market | AC31: =WoodMacInverterCompany!T6 -> 0.76351646 | AD31: =WoodMacInverterCompany!U6 -> 0.23361236 | AE31: =WoodMacInverterCompany!V6 -> 0.002871177
A32: 2018 | P32: 3.1809145e-05 | Q32: % | R32: Yole 2023 slide 72-3 | S32: see yole 2023 sheet | U32: =$B$39*$G$37*P32 -> 1.0751491e-08 | V32: =$B$39*$G$36*P32 -> 6.4508946e-09 | W32: =$B$39*$G$38*$H$38*P32 -> 1.9352684e-08 | Y32: =U32/1000/$Y$1 -> 6.7196819e-09 | Z32: =V32/1000/$Z$1 -> 6.4508946e-10 | AA32: =W32/1000/$AA$1 -> 1.9352684e-11 | AC32: =WoodMacInverterCompany!T7 -> 0.77746515 | AD32: =WoodMacInverterCompany!U7 -> 0.21975854 | AE32: =WoodMacInverterCompany!V7 -> 0.0027763028 | AG32: =(Y32*AC32)+(Z32*AD32)+(AA32*AE32) -> 5.3661362e-09
A33: 2019 | P33: 3.0434452e-05 | Q33: % | R33: Yole 2023 slide 72-3 | S33: see yole 2023 sheet | U33: =$B$39*$G$37*P33 -> 1.0286845e-08 | V33: =$B$39*$G$36*P33 -> 6.1721068e-09 | W33: =$B$39*$G$38*$H$38*P33 -> 1.851632e-08 | Y33: =U33/1000/$Y$1 -> 6.4292779e-09 | Z33: =V33/1000/$Z$1 -> 6.1721068e-10 | AA33: =W33/1000/$AA$1 -> 1.851632e-11 | AC33: =WoodMacInverterCompany!T8 -> 0.81355501 | AD33: =WoodMacInverterCompany!U8 -> 0.18271067 | AE33: =WoodMacInverterCompany!V8 -> 0.0037343167 | AG33: =(Y33*AC33)+(Z33*AD33)+(AA33*AE33) -> 5.3434114e-09
A34: 2020 | P34: 5.419215e-05 | Q34: % | R34: Yole 2023 slide 72-3 | S34: see yole 2023 sheet | U34: =$B$39*$G$37*P34 -> 1.8316947e-08 | V34: =$B$39*$G$36*P34 -> 1.0990168e-08 | W34: =$B$39*$G$38*$H$38*P34 -> 3.2970504e-08 | Y34: =U34/1000/$Y$1 -> 1.1448092e-08 | Z34: =V34/1000/$Z$1 -> 1.0990168e-09 | AA34: =W34/1000/$AA$1 -> 3.2970504e-11 | AC34: =WoodMacInverterCompany!T9 -> 0.81313418 | AD34: =WoodMacInverterCompany!U9 -> 0.17972967 | AE34: =WoodMacInverterCompany!V9 -> 0.0071361511 | AG34: =(Y34*AC34)+(Z34*AD34)+(AA34*AE34) -> 9.5065958e-09
A35: 2021 | G35: 0 | K35: Table S7 says no integrated circuits go to PV applications?? | M35: Han, Zhongkui, Qiance Liu, Xin Ouyang, Huiling Song, Tianming Gao, Yanfei Liu, Bojie Wen, and Tao Dai. 2024. “Tracking Two Decades of Global Gallium Stocks and Flows: A Dynamic Material Flow Analysis.” Resources, Conservation and Recycling 202 (March):107391. https://doi.org/10.1016/j.resconrec.2023.107391. | P35: 8.0580177e-05 | Q35: % | R35: Yole 2023 slide 72-3 | S35: see yole 2023 sheet | U35: =$B$39*$G$37*P35 -> 2.72361e-08 | V35: =$B$39*$G$36*P35 -> 1.634166e-08 | W35: =$B$39*$G$38*$H$38*P35 -> 4.902498e-08 | Y35: =U35/1000/$Y$1 -> 1.7022562e-08 | Z35: =V35/1000/$Z$1 -> 1.634166e-09 | AA35: =W35/1000/$AA$1 -> 4.902498e-11 | AC35: =WoodMacInverterCompany!T10 -> 0.87101307 | AD35: =WoodMacInverterCompany!U10 -> 0.12517984 | AE35: =WoodMacInverterCompany!V10 -> 0.0038070871 | AG35: =(Y35*AC35)+(Z35*AD35)+(AA35*AE35) -> 1.5031626e-08
A36: 2022 | G36: 6 | H36: 1 | I36: 500 V | J36: =10/1000 -> 0.01 | K36: GaN FET/ 10 kW single phase with Battery | L36: STRING | M36: TI reference design 010938 | P36: 0.00019553073 | Q36: % | R36: Yole 2023 slide 72-3 | S36: see yole 2023 sheet | U36: =$B$39*$G$37*P36 -> 6.6089385e-08 | V36: =$B$39*$G$36*P36 -> 3.9653631e-08 | W36: =$B$39*$G$38*$H$38*P36 -> 1.1896089e-07 | Y36: =U36/1000/$Y$1 -> 4.1305866e-08 | Z36: =V36/1000/$Z$1 -> 3.9653631e-09 | AA36: =W36/1000/$AA$1 -> 1.1896089e-10 | AC36: =WoodMacInverterCompany!T11 -> 0.89135783 | AD36: =WoodMacInverterCompany!U11 -> 0.10520776 | AE36: =WoodMacInverterCompany!V11 -> 0.0034344049 | AG36: =(Y36*AC36)+(Z36*AD36)+(AA36*AE36) -> 3.7235903e-08
A37: 2023 | G37: 10 | H37: 1 | I37: 60 Vdc, 240 Vac | J37: =1.6/1000 -> 0.0016 | K37: GaN FET/ 1.6kW microinverter | L37: MICRO | M37: TI reference design 010933 | P37: 0.00033690869 | Q37: % | R37: Yole 2023 slide 72-3 | S37: see yole 2023 sheet | U37: =$B$39*$G$37*P37 -> 1.1387514e-07 | V37: =$B$39*$G$36*P37 -> 6.8325083e-08 | W37: =$B$39*$G$38*$H$38*P37 -> 2.0497525e-07 | Y37: =U37/1000/$Y$1 -> 7.1171961e-08 | Z37: =V37/1000/$Z$1 -> 6.8325083e-09 | AA37: =W37/1000/$AA$1 -> 2.0497525e-10 | AC37: =WoodMacInverterCompany!T12 -> 0.85668735 | AD37: =WoodMacInverterCompany!U12 -> 0.13371819 | AE37: =WoodMacInverterCompany!V12 -> 0.0095944619 | AG37: =(Y37*AC37)+(Z37*AD37)+(AA37*AE37) -> 6.1887716e-08
A38: 2024 | B38: 0.0338 | C38: [mg/FET] | D38: EPC GaN chips data sheets, avg'd, calculated for molar mass of Ga in GaN | E38: see google sheet for avg calc | G38: 6 | H38: 3 | I38: 600, 800, 1000 V | J38: =1 -> 1 | K38: GaN FET/ 3 Phase, 600,800,1000V inverter | L38: UTILITY | M38: TI reference design | N38: Silvana counted 6 in the circuit diagram | P38: 0.00048114949 | Q38: % | R38: Yole 2023 slide 72-3 | S38: see yole 2023 sheet | U38: =$B$39*$G$37*P38 -> 1.6262853e-07 | V38: =$B$39*$G$36*P38 -> 9.7577116e-08 | W38: =$B$39*$G$38*$H$38*P38 -> 2.9273135e-07 | Y38: =U38/1000/$Y$1 -> 1.0164283e-07 | Z38: =V38/1000/$Z$1 -> 9.7577116e-09 | AA38: =W38/1000/$AA$1 -> 2.9273135e-10 | AC38: 0.85668735 | AD38: 0.13371819 | AE38: 0.0095944619 | AG38: =(Y38*AC38)+(Z38*AD38)+(AA38*AE38) -> 8.8383718e-08
A39: 2025 | B39: =B38/1000 -> 3.38e-05 | C39: [g/FET] | H39: 1 | I39: 80 V | J39: =0.6/1000 -> 0.0006 | K39: 600W solar power optimizer reference design based on GaN with wired and wireless communication | M39: TI reference design 010949 | N39: https://www.ti.com/tool/TIDA-010949 | P39: 0.00065715359 | Q39: % | R39: Yole 2023 slide 72-3 | S39: see yole 2023 sheet | U39: =$B$39*$G$37*P39 -> 2.2211791e-07 | V39: =$B$39*$G$36*P39 -> 1.3327075e-07 | W39: =$B$39*$G$38*$H$38*P39 -> 3.9981224e-07 | Y39: =U39/1000/$Y$1 -> 1.388237e-07 | Z39: =V39/1000/$Z$1 -> 1.3327075e-08 | AA39: =W39/1000/$AA$1 -> 3.9981224e-10 | AC39: 0.85668735 | AD39: 0.13371819 | AE39: 0.0095944619 | AG39: =(Y39*AC39)+(Z39*AD39)+(AA39*AE39) -> 1.2071441e-07
A40: 2026 | P40: 0.00091846409 | Q40: % | R40: Yole 2023 slide 72-3 | S40: see yole 2023 sheet | U40: =$B$39*$G$37*P40 -> 3.1044086e-07 | V40: =$B$39*$G$36*P40 -> 1.8626452e-07 | W40: =$B$39*$G$38*$H$38*P40 -> 5.5879355e-07 | Y40: =U40/1000/$Y$1 -> 1.9402554e-07 | Z40: =V40/1000/$Z$1 -> 1.8626452e-08 | AA40: =W40/1000/$AA$1 -> 5.5879355e-10 | AC40: 0.85668735 | AD40: 0.13371819 | AE40: 0.0095944619 | AG40: =(Y40*AC40)+(Z40*AD40)+(AA40*AE40) -> 1.6871528e-07
A41: 2027 | P41: 0.0010283067 | Q41: % | R41: Yole 2023 slide 72-3 | S41: see yole 2023 sheet | U41: =$B$39*$G$37*P41 -> 3.4756766e-07 | V41: =$B$39*$G$36*P41 -> 2.085406e-07 | W41: =$B$39*$G$38*$H$38*P41 -> 6.2562179e-07 | Y41: =U41/1000/$Y$1 -> 2.1722979e-07 | Z41: =V41/1000/$Z$1 -> 2.085406e-08 | AA41: =W41/1000/$AA$1 -> 6.2562179e-10 | AC41: 0.85668735 | AD41: 0.13371819 | AE41: 0.0095944619 | AG41: =(Y41*AC41)+(Z41*AD41)+(AA41*AE41) -> 1.8889258e-07
A42: 2028 | P42: 0.0011831442 | Q42: % | R42: Yole 2023 slide 72-3 | S42: see yole 2023 sheet | U42: =$B$39*$G$37*P42 -> 3.9990276e-07 | V42: =$B$39*$G$36*P42 -> 2.3994165e-07 | W42: =$B$39*$G$38*$H$38*P42 -> 7.1982496e-07 | Y42: =U42/1000/$Y$1 -> 2.4993922e-07 | Z42: =V42/1000/$Z$1 -> 2.3994165e-08 | AA42: =W42/1000/$AA$1 -> 7.1982496e-10 | AC42: 0.85668735 | AD42: 0.13371819 | AE42: 0.0095944619 | AG42: =(Y42*AC42)+(Z42*AD42)+(AA42*AE42) -> 2.1733513e-07
A43: 2029 | AC43: 0.85668735 | AD43: 0.13371819 | AE43: 0.0095944619
A44: 2030 | AC44: 0.85668735 | AD44: 0.13371819 | AE44: 0.0095944619
A45: 2031 | AC45: 0.85668735 | AD45: 0.13371819 | AE45: 0.0095944619
A46: 2032 | AC46: 0.85668735 | AD46: 0.13371819 | AE46: 0.0095944619
...

Sheet yole2023
A1: slide 56 | B1: Power Electronics Market Revenue Value by material
B2: [$M]?
B3: SiC | C3: GaN | D3: Silicon | E3: Total Market value | F3: SiC | G3: GaN | H3: Silicon | J3: *check for a material value
A4: 2018 | B4: 0.4 | C4: 0 | D4: 15.7 | E4: =SUM(B4:D4) -> 16.1 | F4: =B4/$E4 -> 0.02484472 | G4: =C4/$E4 -> 0 | H4: =D4/$E4 -> 0.97515528
A5: 2019 | B5: 0.6 | C5: 0.01 | D5: 16.5 | E5: =SUM(B5:D5) -> 17.11 | F5: =B5/$E5 -> 0.035067212 | G5: =C5/$E5 -> 0.00058445354 | H5: =D5/$E5 -> 0.96434833
A6: 2020 | B6: 0.7 | C6: 0.02 | D6: 16.5 | E6: =SUM(B6:D6) -> 17.22 | F6: =B6/$E6 -> 0.040650407 | G6: =C6/$E6 -> 0.0011614402 | H6: =D6/$E6 -> 0.95818815
A7: 2021 | B7: 1.2 | C7: 0.1 | D7: 18.1 | E7: =SUM(B7:D7) -> 19.4 | F7: =B7/$E7 -> 0.06185567 | G7: =C7/$E7 -> 0.0051546392 | H7: =D7/$E7 -> 0.93298969
A8: 2022 | B8: 1.9 | C8: 0.1 | D8: 19.3 | E8: =SUM(B8:D8) -> 21.3 | F8: =B8/$E8 -> 0.089201878 | G8: =C8/$E8 -> 0.0046948357 | H8: =D8/$E8 -> 0.90610329
A9: 2023 | B9: 2.9 | C9: 0.1 | D9: 20 | E9: =SUM(B9:D9) -> 23 | F9: =B9/$E9 -> 0.12608696 | G9: =C9/$E9 -> 0.0043478261 | H9: =D9/$E9 -> 0.86956522
A10: 2024 | B10: 4 | C10: 0.2 | D10: 21 | E10: =SUM(B10:D10) -> 25.2 | F10: =B10/$E10 -> 0.15873016 | G10: =C10/$E10 -> 0.0079365079 | H10: =D10/$E10 -> 0.83333333
A11: 2025 | B11: 5.2 | C11: 0.3 | D11: 22 | E11: =SUM(B11:D11) -> 27.5 | F11: =B11/$E11 -> 0.18909091 | G11: =C11/$E11 -> 0.010909091 | H11: =D11/$E11 -> 0.8
A12: 2026 | B12: 6.4 | C12: 0.5 | D12: 23 | E12: =SUM(B12:D12) -> 29.9 | F12: =B12/$E12 -> 0.21404682 | G12: =C12/$E12 -> 0.016722408 | H12: =D12/$E12 -> 0.76923077
A13: 2027 | B13: 7.8 | C13: 0.7 | D13: 23.7 | E13: =SUM(B13:D13) -> 32.2 | F13: =B13/$E13 -> 0.24223602 | G13: =C13/$E13 -> 0.02173913 | H13: =D13/$E13 -> 0.73602484
A14: 2028 | B14: 9.4 | C14: 1 | D14: 24 | E14: =SUM(B14:D14) -> 34.4 | F14: =B14/$E14 -> 0.27325581 | G14: =C14/$E14 -> 0.029069767 | H14: =D14/$E14 -> 0.69767442
C15: *keeps being used in power supply consumer applications
A17: Slide 72-73 | B17: Discrete GaN HEMT market revenue forcast by application
B18: [$M] | D18: Total power electronics discrete market
B19: % GaN in PV | C19: PV GaN HEMT | D19: Total GaN HEMT market | E19: PV power electronics market, all technologies | F19: Total Market revenue, all sectors
A20: 2018 | B20: =C20/F20 -> 3.1809145e-05 | C20: 0.4 | D20: 4 | E20: 170 | F20: 12575
A21: 2019 | B21: =C21/F21 -> 3.0434452e-05 | C21: 0.4 | D21: 9 | E21: 209 | F21: 13143
A22: 2020 | B22: =C22/F22 -> 5.419215e-05 | C22: 0.7 | D22: 24 | E22: 212 | F22: 12917
A23: 2021 | B23: =C23/F23 -> 8.0580177e-05 | C23: 1.1 | D23: 66 | E23: 288 | F23: 13651
A24: 2022 | B24: =C24/F24 -> 0.00019553073 | C24: 2.8 | D24: 93 | E24: 409 | F24: 14320
A25: 2023 | B25: =C25/F25 -> 0.00033690869 | C25: 4.9 | D25: 148 | E25: 510 | F25: 14544
A26: 2024 | B26: =C26/F26 -> 0.00048114949 | C26: 7.3 | D26: 183 | E26: 576 | F26: 15172
A27: 2025 | B27: =C27/F27 -> 0.00065715359 | C27: 10.5 | D27: 295 | E27: 626 | F27: 15978
A28: 2026 | B28: =C28/F28 -> 0.00091846409 | C28: 15.5 | D28: 482 | E28: 675 | F28: 16876
A29: 2027 | B29: =C29/F29 -> 0.0010283067 | C29: 18.2 | D29: 691 | E29: 721 | F29: 17699
A30: 2028 | B30: =C30/F30 -> 0.0011831442 | C30: 21.9 | D30: 991 | E30: 759 | F30: 18510

Sheet WoodMacInverterCompany
B1: Mwac | I1: % (on power basis) | M1: # of inverter units of each type | T1: % (on unit basis)
L2: AVG MW rating: | M2: =1600/1000000 -> 0.0016 | N2: =10/1000 -> 0.01 | O2: =10/1000 -> 0.01 | P2: 1 | Q2: =1600/1000000 -> 0.0016
B3: Total PV inverter shipments | C3: Microinverter | D3: Single-phase String | E3: Three-phase String | F3: Central | G3: Hybrid | I3: Microinverter | J3: String | K3: Central | M3: Microinverter | N3: Single-phase String | O3: Three-phase String | P3: Central | Q3: Hybrid | R3: TOTAL UNITS | T3: Microinverter | U3: String | V3: Central
A4: 2015 | B4: =D181 -> 9904 | C4: =H181 -> 1516 | D4: =L181 -> 2120 | E4: =P181 -> 1105 | F4: =T181 -> 6190 | G4: 0 | I4: =(C4+G4)/B4 -> 0.15306947 | J4: =(D4+E4)/B4 -> 0.32562601 | K4: =F4/B4 -> 0.625 | M4: =C4/M$2 -> 947500 | N4: =D4/N$2 -> 212000 | O4: =E4/O$2 -> 110500 | P4: =F4/P$2 -> 6190 | Q4: =G4/Q$2 -> 0 | R4: =SUM(M4:Q4) -> 1276190 | T4: =(Q4+M4)/R4 -> 0.74244431 | U4: =(N4+O4)/R4 -> 0.25270532 | V4: =P4/R4 -> 0.0048503749
A5: 2016 | B5: =D164 -> 13817 | C5: =H164 -> 1923 | D5: =L164 -> 1829 | E5: =P164 -> 2025 | F5: =T164 -> 9194 | G5: 0 | I5: =(C5+G5)/B5 -> 0.13917638 | J5: =(D5+E5)/B5 -> 0.27893175 | K5: =F5/B5 -> 0.66541217 | M5: =C5/M$2 -> 1201875 | N5: =D5/N$2 -> 182900 | O5: =E5/O$2 -> 202500 | P5: =F5/P$2 -> 9194 | Q5: =G5/Q$2 -> 0 | R5: =SUM(M5:Q5) -> 1596469 | T5: =(Q5+M5)/R5 -> 0.75283328 | U5: =(N5+O5)/R5 -> 0.24140776 | V5: =P5/R5 -> 0.0057589593
A6: 2017 | B6: =D145 -> 9600 | C6: =H145 -> 2064 | D6: =L145 -> 1664 | E6: =P145 -> 2283 | F6: =T145 -> 4851 | G6: 0 | I6: =(C6+G6)/B6 -> 0.215 | J6: =(D6+E6)/B6 -> 0.41114583 | K6: =F6/B6 -> 0.5053125 | M6: =C6/M$2 -> 1290000 | N6: =D6/N$2 -> 166400 | O6: =E6/O$2 -> 228300 | P6: =F6/P$2 -> 4851 | Q6: =G6/Q$2 -> 0 | R6: =SUM(M6:Q6) -> 1689551 | T6: =(Q6+M6)/R6 -> 0.76351646 | U6: =(N6+O6)/R6 -> 0.23361236 | V6: =P6/R6 -> 0.002871177
A7: 2018 | B7: =D122 -> 11583.953 | C7: =H122 -> 2651.4249 | D7: =L122 -> 1876.7812 | E7: =P122 -> 2807.2974 | F7: =T122 -> 5917.595 | G7: 0 | I7: =(C7+G7)/B7 -> 0.22888775 | J7: =(D7+E7)/B7 -> 0.40435927 | K7: =F7/B7 -> 0.5108442 | M7: =C7/M$2 -> 1657140.5 | N7: =D7/N$2 -> 187678.12 | O7: =E7/O$2 -> 280729.74 | P7: =F7/P$2 -> 5917.595 | Q7: =G7/Q$2 -> 0 | R7: =SUM(M7:Q7) -> 2131466 | T7: =(Q7+M7)/R7 -> 0.77746515 | U7: =(N7+O7)/R7 -> 0.21975854 | V7: =P7/R7 -> 0.0027763028
A8: 2019 | B8: =D103 -> 18470.21 | C8: =H103 -> 3821.49 | D8: =L103 -> 2277.16 | E8: =P103 -> 3260.96 | F8: =T103 -> 11319.04 | G8: =Y103 -> 124.04 | I8: =(C8+G8)/B8 -> 0.21361587 | J8: =(D8+E8)/B8 -> 0.29984066 | K8: =F8/B8 -> 0.61282682 | M8: =C8/M$2 -> 2388431.2 | N8: =D8/N$2 -> 227716 | O8: =E8/O$2 -> 326096 | P8: =F8/P$2 -> 11319.04 | Q8: =G8/Q$2 -> 77525 | R8: =SUM(M8:Q8) -> 3031087.3 | T8: =(Q8+M8)/R8 -> 0.81355501 | U8: =(N8+O8)/R8 -> 0.18271067 | V8: =P8/R8 -> 0.0037343167
A9: 2020 | B9: =D87 -> 30854.86 | C9: =H87 -> 4039.47 | D9: =L87 -> 1912.89 | E9: =P87 -> 3935.58 | F9: =T87 -> 23221.3 | G9: =Y87 -> 194.08 | I9: =(C9+G9)/B9 -> 0.13720853 | J9: =(D9+E9)/B9 -> 0.18954777 | K9: =F9/B9 -> 0.75259781 | M9: =C9/M$2 -> 2524668.7 | N9: =D9/N$2 -> 191289 | O9: =E9/O$2 -> 393558 | P9: =F9/P$2 -> 23221.3 | Q9: =G9/Q$2 -> 121300 | R9: =SUM(M9:Q9) -> 3254037 | T9: =(Q9+M9)/R9 -> 0.81313418 | U9: =(N9+O9)/R9 -> 0.17972967 | V9: =P9/R9 -> 0.0071361511
A10: 2021 | B10: =D70 -> 30493.785 | C10: =H70 -> 5522.466 | D10: =L70 -> 1915.4572 | E10: =P70 -> 4564.4751 | F10: =T70 -> 19707.379 | G10: =Y70 -> 1691.6102 | I10: =(C10+G10)/B10 -> 0.23657529 | J10: =(D10+E10)/B10 -> 0.2125001 | K10: =F10/B10 -> 0.64627528 | M10: =C10/M$2 -> 3451541.2 | N10: =D10/N$2 -> 191545.72 | O10: =E10/O$2 -> 456447.51 | P10: =F10/P$2 -> 19707.379 | Q10: =G10/Q$2 -> 1057256.4 | R10: =SUM(M10:Q10) -> 5176498.2 | T10: =(Q10+M10)/R10 -> 0.87101307 | U10: =(N10+O10)/R10 -> 0.12517984 | V10: =P10/R10 -> 0.0038070871
A11: 2022 | B11: =D53 -> 45536 | C11: =H53 -> 7538 | D11: =L53 -> 3790 | E11: =P53 -> 4978.22 | F11: =T53 -> 28623 | G11: =Y53 -> 4348 | I11: =(C11+G11)/B11 -> 0.26102424 | J11: =(D11+E11)/B11 -> 0.19255578 | K11: =F11/B11 -> 0.62857959 | M11: =C11/M$2 -> 4711250 | N11: =D11/N$2 -> 379000 | O11: =E11/O$2 -> 497822 | P11: =F11/P$2 -> 28623 | Q11: =G11/Q$2 -> 2717500 | R11: =SUM(M11:Q11) -> 8334195 | T11: =(Q11+M11)/R11 -> 0.89135783 | U11: =(N11+O11)/R11 -> 0.10520776 | V11: =P11/R11 -> 0.0034344049
A12: 2023 | B12: =D37 -> 48217.542 | C12: =H37 -> 3371.8142 | D12: =L37 -> 470.94815 | E12: =P37 -> 4769.974 | F12: =T37 -> 37604.329 | G12: =X37 -> 2000.4771 | I12: =(C12+G12)/B12 -> 0.11141778 | J12: =(D12+E12)/B12 -> 0.10869327 | K12: =F12/B12 -> 0.77988896 | M12: =C12/M$2 -> 2107383.9 | N12: =D12/N$2 -> 47094.815 | O12: =E12/O$2 -> 476997.4 | P12: =F12/P$2 -> 37604.329 | Q12: =G12/Q$2 -> 1250298.2 | R12: =SUM(M12:Q12) -> 3919378.6 | T12: =(Q12+M12)/R12 -> 0.85668735 | U12: =(N12+O12)/R12 -> 0.13371819 | V12: =P12/R12 -> 0.0095944619
A13: 2024
B24: 2023 PV inverter shipments (MWac) | C24: United States total PV inverter market share (% of shipped MWac) | G24: US microinverter market share (% of shipped MWac) | K24: US single-phase string inverter market share (% of shipped MWac) | O24: US three-phase string inverter market share (% of shipped MWac) | S24: US central inverter market share (% of shipped MWac) | W24: US DC-coupled hybrid inverter market share (% of shipped MWac)
B25: Ranking | C25: Company | D25: Market Share | F25: Ranking | G25: Company | H25: Market Share | J25: Ranking | K25: Company | L25: Market Share | N25: Ranking | O25: Company | P25: Market Share | R25: Ranking | S25: Company | T25: Market Share | V25: Ranking | W25: Company | X25: Market Share
B26: 1 | C26: Sungrow* | D26: 0.30393992 | F26: 1 | G26: Enphase | H26: 0.9054298 | J26: 1 | K26: SolarEdge* | L26: 0.56331412 | N26: 1 | O26: Chint Power Systems | P26: 0.31924702 | R26: 1 | S26: Sungrow* | T26: 0.36234318 | V26: 1 | W26: SolarEdge* | X26: 0.91452135
B27: 2 | C27: Power Electronics | D27: 0.1885206 | F27: 2 | G27: Hoymiles | H27: 0.041520674 | J27: 2 | K27: SMA | L27: 0.11678568 | N27: 2 | O27: SMA | P27: 0.23689857 | R27: 2 | S27: Power Electronics | T27: 0.24172749 | V27: 2 | W27: Growatt | X27: 0.048863344
B28: 3 | C28: GE Vernova | D28: 0.1161403 | F28: 3 | G28: APsystems* | H28: 0.030331787 | J28: 3 | K28: Ginlong Solis | L28: 0.10788002 | N28: 3 | O28: Sungrow* | P28: 0.21584268 | R28: 3 | S28: GE Vernova | T28: 0.14891903 | V28: 3 | W28: GoodWe | X28: 0.020395135
B29: 4 | C29: TMEIC | D29: 0.10523141 | F29: 4 | G29: NEP | H29: 0.02271774 | J29: 4 | K29: Growatt | L29: 0.097508824 | N29: 4 | O29: SolarEdge* | P29: 0.10328875 | R29: 4 | S29: TMEIC | T29: 0.13493127
B30: 5 | C30: SMA | D30: 0.072380297 | J30: 5 | K30: Fronius | L30: 0.083074751 | N30: 5 | O30: Ginlong Solis | P30: 0.050258088 | R30: 5 | S30: SMA | T30: 0.061163171
B31: 6 | C31: Enphase | D31: 0.063315983 | J31: 6 | K31: Fimer* | L31: 0.031436605 | N31: 6 | O31: Yaskawa Solectria | P31: 0.041308401 | R31: 6 | S31: Ingeteam | T31: 0.025438295
B32: 7 | C32: SolarEdge | D32: 0.053662117 | N32: 7 | O32: Fimer* | P32: 0.028239043 | R32: 7 | S32: Gamesa | T32: 0.025263049
B33: 8 | C33: Chint Power Systems | D33: 0.031581867
B34: 9 | C34: Ingeteam | D34: 0.019839045
B35: 10 | C35: Gamesa | D35: 0.019702373
C36: All Others | D36: 0.025686077 | W36: All Others | X36: 0.016220175
B37: 2023 PV inverter shipments (MWac) | D37: 48217.542 | F37: 2023 PV inverter shipments (MWac) | H37: 3371.8142 | J37: 2023 PV inverter shipments (MWac) | L37: 470.94815 | N37: 2023 PV inverter shipments (MWac) | P37: 4769.974 | R37: 2023 PV inverter shipments (MWac) | T37: 37604.329 | V37: 2023 PV inverter shipments (MWac) | X37: 2000.4771
B39: US market shares by product type shipments full-year 2022 | J39: * Estimate
B41: United States PV inverter market share by shipments (MWac) | F41: US MLPE Market Share by shipments (MWac) | J41: US Single-Phase String Market Share by shipments (MWac) | N41: US Three-Phase String Market Share by shipments (MWac) | R41: US Central inverter market share by shipments (MWac) | V41: US Storage Hybrid Market Share by shipments (MWac)
B42: Ranking | C42: Company | D42: Market Share | F42: Ranking | G42: Company | H42: Market Share | J42: Ranking | K42: Company | L42: Market Share | N42: Ranking | O42: Company | P42: Market Share | R42: Ranking | S42: Company | T42: Market Share | V42: Ranking | W42: Company | Y42: Market Share
B43: 1 | C43: Sungrow | D43: 0.20218961 | F43: 1 | G43: Enphase Energy | H43: 0.46120002 | J43: 1 | K43: SolarEdge | L43: 0.88311346 | N43: 1 | O43: Chint Power Systems | P43: 0.4844514 | R43: 1 | S43: Power Electronics | T43: 0.38058079 | V43: 1 | W43: SolarEdge Technologies | Y43: 0.56113668
B44: 2 | C44: Power Electronics | D44: 0.17788139 | F44: 2 | G44: SolarEdge Technologies | H44: 0.44399568 | J44: 2 | K44: Sungrow | L44: 0.065768307 | N44: 2 | O44: Sungrow | P44: 0.33391236 | R44: 2 | S44: TMEIC | T44: 0.25699761 | V44: 2 | W44: Sungrow | Y44: 0.31760093
B45: 3 | C45: TMEIC | D45: 0.1404367 | F45: 3 | G45: Tigo | H45: 0.059700193 | J45: 3 | K45: SMA | L45: 0.029486344 | N45: 3 | O45: SMA | P45: 0.12262232 | R45: 3 | S45: Sungrow | T45: 0.14720374 | V45: 3 | W45: SMA | Y45: 0.05238881
B46: 4 | C46: SolarEdge Technologies | D46: 0.12708626 | F46: 4 | G46: Ampt | H46: 0.018002925 | J46: 4 | K46: Fronius | L46: 0.010170498 | N46: 4 | O46: Ginlong Solis | P46: 0.033604183 | R46: 4 | S46: General Electric | T46: 0.1020978 | V46: 4 | W46: Growatt | Y46: 0.040839354
B47: 5 | C47: General Electric | D47: 0.098822995 | J47: 5 | K47: Ginlong Solis | L47: 0.0076227286 | N47: 5 | O47: Fimer | P47: 0.020715962 | R47: 5 | S47: SMA | T47: 0.071039379 | V47: 5 | W47: GoodWe | Y47: 0.025297494
B48: 6 | C48: Enphase Energy | D48: 0.076343417 | R48: 6 | S48: Ingeteam | T48: 0.041710264
B49: 7 | C49: SMA | D49: 0.071982358
B50: 8 | C50: Chint Power Systems | D50: 0.05321245
B51: 9 | C51: Ingeteam | D51: 0.025522686
C52: All Others | D52: 0.026522133 | G52: All Others | H52: 0.02 | K52: All Others | L52: 0.01
...
